Watching for file changes with StatReloader
"GET / HTTP/1.1" 200 23
"GET /login/ HTTP/1.1" 200 585
Internal Server Error: /login/
Traceback (most recent call last):
  File "/anaconda3/envs/CSE-545-Group-8-development/lib/python3.7/site-packages/django/db/backends/utils.py", line 86, in _execute
    return self.cursor.execute(sql, params)
  File "/anaconda3/envs/CSE-545-Group-8-development/lib/python3.7/site-packages/django/db/backends/sqlite3/base.py", line 396, in execute
    return Database.Cursor.execute(self, query, params)
sqlite3.OperationalError: no such table: auth_user

The above exception was the direct cause of the following exception:

Traceback (most recent call last):
  File "/anaconda3/envs/CSE-545-Group-8-development/lib/python3.7/site-packages/django/core/handlers/exception.py", line 34, in inner
    response = get_response(request)
  File "/anaconda3/envs/CSE-545-Group-8-development/lib/python3.7/site-packages/django/core/handlers/base.py", line 115, in _get_response
    response = self.process_exception_by_middleware(e, request)
  File "/anaconda3/envs/CSE-545-Group-8-development/lib/python3.7/site-packages/django/core/handlers/base.py", line 113, in _get_response
    response = wrapped_callback(request, *callback_args, **callback_kwargs)
  File "/Users/zhangziming/Documents/cse545project/login/views.py", line 24, in login_user
    userObj = authenticate(username=form.cleaned_data['user_id'], password=form.cleaned_data['password'])
  File "/anaconda3/envs/CSE-545-Group-8-development/lib/python3.7/site-packages/django/contrib/auth/__init__.py", line 72, in authenticate
    user = backend.authenticate(request, **credentials)
  File "/anaconda3/envs/CSE-545-Group-8-development/lib/python3.7/site-packages/django/contrib/auth/backends.py", line 46, in authenticate
    user = UserModel._default_manager.get_by_natural_key(username)
  File "/anaconda3/envs/CSE-545-Group-8-development/lib/python3.7/site-packages/django/contrib/auth/base_user.py", line 44, in get_by_natural_key
    return self.get(**{self.model.USERNAME_FIELD: username})
  File "/anaconda3/envs/CSE-545-Group-8-development/lib/python3.7/site-packages/django/db/models/manager.py", line 82, in manager_method
    return getattr(self.get_queryset(), name)(*args, **kwargs)
  File "/anaconda3/envs/CSE-545-Group-8-development/lib/python3.7/site-packages/django/db/models/query.py", line 411, in get
    num = len(clone)
  File "/anaconda3/envs/CSE-545-Group-8-development/lib/python3.7/site-packages/django/db/models/query.py", line 258, in __len__
    self._fetch_all()
  File "/anaconda3/envs/CSE-545-Group-8-development/lib/python3.7/site-packages/django/db/models/query.py", line 1261, in _fetch_all
    self._result_cache = list(self._iterable_class(self))
  File "/anaconda3/envs/CSE-545-Group-8-development/lib/python3.7/site-packages/django/db/models/query.py", line 57, in __iter__
    results = compiler.execute_sql(chunked_fetch=self.chunked_fetch, chunk_size=self.chunk_size)
  File "/anaconda3/envs/CSE-545-Group-8-development/lib/python3.7/site-packages/django/db/models/sql/compiler.py", line 1144, in execute_sql
    cursor.execute(sql, params)
  File "/anaconda3/envs/CSE-545-Group-8-development/lib/python3.7/site-packages/django/db/backends/utils.py", line 100, in execute
    return super().execute(sql, params)
  File "/anaconda3/envs/CSE-545-Group-8-development/lib/python3.7/site-packages/django/db/backends/utils.py", line 68, in execute
    return self._execute_with_wrappers(sql, params, many=False, executor=self._execute)
  File "/anaconda3/envs/CSE-545-Group-8-development/lib/python3.7/site-packages/django/db/backends/utils.py", line 77, in _execute_with_wrappers
    return executor(sql, params, many, context)
  File "/anaconda3/envs/CSE-545-Group-8-development/lib/python3.7/site-packages/django/db/backends/utils.py", line 86, in _execute
    return self.cursor.execute(sql, params)
  File "/anaconda3/envs/CSE-545-Group-8-development/lib/python3.7/site-packages/django/db/utils.py", line 90, in __exit__
    raise dj_exc_value.with_traceback(traceback) from exc_value
  File "/anaconda3/envs/CSE-545-Group-8-development/lib/python3.7/site-packages/django/db/backends/utils.py", line 86, in _execute
    return self.cursor.execute(sql, params)
  File "/anaconda3/envs/CSE-545-Group-8-development/lib/python3.7/site-packages/django/db/backends/sqlite3/base.py", line 396, in execute
    return Database.Cursor.execute(self, query, params)
django.db.utils.OperationalError: no such table: auth_user
"POST /login/ HTTP/1.1" 500 149019
/Users/zhangziming/Documents/cse545project/manage.py changed, reloading.
Watching for file changes with StatReloader
"GET / HTTP/1.1" 200 23
"GET /login/ HTTP/1.1" 200 585
"POST /login/ HTTP/1.1" 302 0
"GET /user_home/ HTTP/1.1" 200 185
"GET /user_home/logout/ HTTP/1.1" 302 0
"GET / HTTP/1.1" 200 23
"GET /login/ HTTP/1.1" 200 585
"POST /login/ HTTP/1.1" 200 42
"GET /login/ HTTP/1.1" 200 585
